<?xml version="1.0" ?>
<!-- =================================================================================== -->
<!-- |    This document was autogenerated by xacro from xacro/m92_robot.xacro          | -->
<!-- |    EDITING THIS FILE BY HAND IS NOT RECOMMENDED                                 | -->
<!-- =================================================================================== -->
<robot name="M92C3">
  <mujoco>
        <compiler 
        meshdir="meshes" 
        balanceinertia="true" 
        discardvisual="false" />
  </mujoco>
  <!-- <xacro:property name="wrist_x_x" value="0" />
    <xacro:property name="wrist_x_y" value="-10e-3" />
    <xacro:property name="wrist_x_z" value="-304.11e-3"/> -->
  <!-- <xacro:property name="wrist_x_x" value="0.04031274e-3" />
    <xacro:property name="wrist_x_y" value="9.99999991e-3" />
    <xacro:property name="wrist_x_z" value="-304.199997283e-3"/> -->
  <!-- <xacro:property name="thumb_distal_length" value="16.47e-3" /> -->
  <!-- link mass & center of mass  -->
  <!-- link inertia -->
  <!-- joint offset -->
  <!-- <xacro:property name="shoulder_y_r" value="0.086933628311361" />
    <xacro:property name="shoulder_y_yy" value="-0.086933628311361" />
    <xacro:property name="shoulder_y_x" value="-46.478e-3" />
    <xacro:property name="shoulder_y_y" value="-236.712e-3" />
    <xacro:property name="shoulder_y_z" value="357.157e-3" /> -->
  <!-- link mass & center of mass  -->
  <!-- link inertia -->
  <link name="base">
    <inertial>
      <origin rpy="0.0 0.0 0.0" xyz="0.0 0.0 0.0"/>
      <mass value="0.001"/>
      <inertia ixx="0.0001" ixy="0.0" ixz="0.0" iyy="0.0001" iyz="0.0" izz="0.0001"/>
    </inertial>
  </link>
  <joint name="floating_base" type="fixed">
    <origin rpy="0 0 0" xyz="0 0 0.0"/>
    <parent link="base"/>
    <child link="pelvis"/>
  </joint>
  <link name="pelvis">
    <inertial>
      <origin rpy="0.0 0.0 0.0" xyz="-0.047079828 4.1067263e-05 -0.045706047"/>
      <mass value="4.628075593"/>
      <inertia ixx="0.026342995" ixy="0.00016805098" ixz="0.00034096711" iyy="0.0069603497" iyz="-0.00017749457" izz="0.028461238"/>
    </inertial>
    <visual>
      <origin rpy="0.0 0.0 0.0" xyz="0.0 0.0 0.0"/>
      <geometry>
        <mesh filename="meshes/pelvis.stl" scale="1e-3 1e-3 1e-3"/>
        <!-- <mesh filename="/home/yinghao/catkin_ws_M92/src/hemera_control/robot_config_manager/m92_description/M92C3/meshes/pelvis.stl" scale="1e-3 1e-3 1e-3"/> -->
      </geometry>
    </visual>
    <collision>
      <origin rpy="0.0 0.0 0.0" xyz="0.0 0.0 0.0"/>
      <geometry>
        <mesh filename="meshes/pelvis.stl" scale="1e-3 1e-3 1e-3"/>
        <!-- <mesh filename="/home/yinghao/catkin_ws_M92/src/hemera_control/robot_config_manager/m92_description/M92C3/meshes/pelvis.stl" scale="1e-3 1e-3 1e-3"/> -->

      </geometry>
    </collision>
  </link>
  <joint name="WA_WAIST1_Y" type="revolute">
    <origin rpy="0.0 0.0 0.0" xyz="-0.0669241 0 0.0593373"/>
    <parent link="pelvis"/>
    <child link="abdomen"/>
    <axis xyz="0.0 0.0 1.0"/>
    <limit effort="200" lower="-1.0472" upper="1.0472" velocity="6"/>
  </joint>
  <link name="abdomen">
    <inertial>
      <origin rpy="0.0 0.0 0.0" xyz="0.050788279 -0.0058522684 -0.011582642"/>
      <mass value="5.214298502"/>
      <inertia ixx="0.015813565" ixy="-0.0011413695" ixz="-0.0067026694" iyy="0.028176136" iyz="-0.0025580929" izz="0.023804555"/>
    </inertial>
    <visual>
      <origin rpy="0.0 0.0 0.0" xyz="0.0 0.0 0.0"/>
      <geometry>
        <mesh filename="meshes/abdomen.stl" scale="1e-3 1e-3 1e-3"/>
      </geometry>
    </visual>
    <collision>
      <origin rpy="0.0 0.0 0.0" xyz="0.0 0.0 0.0"/>
      <geometry>
        <mesh filename="meshes/abdomen.stl" scale="1e-3 1e-3 1e-3"/>
      </geometry>
    </collision>
  </link>
  <joint name="WA_WAIST2_P" type="revolute">
    <origin rpy="0.0 0.0 0.0" xyz="0.1 0 0"/>
    <parent link="abdomen"/>
    <child link="trunk"/>
    <axis xyz="0.0 1.0 0.0"/>
    <limit effort="200" lower="-0.001" upper="1.2217" velocity="6"/>
    
  </joint>
  <link name="trunk">
    <inertial>
      <origin rpy="0.0 0.0 0.0" xyz="-0.038466273 -0.0015539492 0.29004437"/>
      <mass value="21.489365477"/>
      <inertia ixx="0.69137989" ixy="0.0012201606" ixz="-0.062726419" iyy="0.64189133" iyz="-0.00032591042" izz="0.20502654"/>
    </inertial>
    <visual>
      <origin rpy="0.0 0.0 0.0" xyz="0.0 0.0 0.0"/>
      <geometry>
        <mesh filename="meshes/trunk.stl" scale="1e-3 1e-3 1e-3"/>
      </geometry>
    </visual>
    <collision>
      <origin rpy="0.0 0.0 0.0" xyz="0.0 0.0 0.0"/>
      <geometry>
        <mesh filename="meshes/trunk.stl" scale="1e-3 1e-3 1e-3"/>
      </geometry>
    </collision>
  </link>
  <joint name="L_LEG1_HIP_Y" type="revolute">
    <origin rpy="0 0.7854 0" xyz="-0.108293 0.075 -0.108293"/>
    <parent link="pelvis"/>
    <child link="L_buttock"/>
    <axis xyz="0.0 0.0 1.0"/>
    <limit effort="200" lower="-0.7854" upper="1.5708" velocity="22.19"/>
    
  </joint>
  <link name="L_buttock">
    <inertial>
      <origin rpy="0.0 0.0 0.0" xyz="0.0024957564 -1.2623423e-05 0.0046982699"/>
      <mass value="1.563261089"/>
      <inertia ixx="0.0019951068" ixy="-2.0533928e-07" ixz="-1.6097655e-05" iyy="0.0016946848" iyz="-1.8301724e-07" izz="0.0014133439"/>
    </inertial>
    <visual>
      <geometry>
        <mesh filename="meshes/buttock.stl" scale="1e-3 1e-3 1e-3"/>
      </geometry>
    </visual>
    <collision>
      <origin rpy="0 0 0" xyz="0 0 0"/>
      <geometry>
        <mesh filename="meshes/buttock.stl" scale="1e-3 1e-3 1e-3"/>
      </geometry>
    </collision>
  </link>
  <joint name="L_LEG2_HIP_R" type="revolute">
    <origin rpy="0.0 0.0 0.0" xyz="0 0 0"/>
    <parent link="L_buttock"/>
    <child link="L_leg"/>
    <axis xyz="1.0 0.0 0.0"/>
    <limit effort="100" lower="-0.7854" upper="0.7854" velocity="20.22"/>
    
  </joint>
  <link name="L_leg">
    <inertial>
      <origin rpy="0.0 0.0 0.0" xyz="0.14868123 0.0035540022 0.00010724939"/>
      <mass value="4.113844972"/>
      <inertia ixx="0.011591155" ixy="-4.1774824e-05" ixz="-9.045867e-05" iyy="0.023555436" iyz="1.3727523e-05" izz="0.013497663"/>
    </inertial>
    <visual>
      <origin rpy="3.1415926 0 0" xyz="0 0 0"/>
      <geometry>
        <mesh filename="meshes/leg.stl" scale="1e-3 1e-3 1e-3"/>
      </geometry>
    </visual>
    <collision>
      <origin rpy="3.1415926 0 0" xyz="0 0 0"/>
      <geometry>
        <mesh filename="meshes/leg.stl" scale="1e-3 1e-3 1e-3"/>
      </geometry>
    </collision>
  </link>
  <joint name="L_LEG3_HIP_P" type="revolute">
    <origin rpy="0.0 -0.7854 0.0" xyz="0.1575 0 0"/>
    <parent link="L_leg"/>
    <child link="L_thigh"/>
    <axis xyz="0.0 1.0 0.0"/>
    <limit effort="350" lower="-2.3213" upper="1.3614" velocity="27.27"/>
    
  </joint>
  <link name="L_thigh">
    <inertial>
      <origin rpy="0.0 0.0 0.0" xyz="0.0022347405 0.065808797 -0.065517537"/>
      <mass value="6.901348888"/>
      <inertia ixx="0.07943384" ixy="3.6874363e-05" ixz="0.0037803199" iyy="0.088740509" iyz="-0.0058211808" izz="0.020469118"/>
    </inertial>
    <visual>
      <geometry>
        <mesh filename="meshes/mthigh.stl" scale="1e-3 1e-3 1e-3"/>
      </geometry>
    </visual>
    <collision>
      <origin rpy="0 0 0" xyz="0 0 0"/>
      <geometry>
        <mesh filename="meshes/mthigh.stl" scale="1e-3 1e-3 1e-3"/>
      </geometry>
    </collision>
  </link>
  <joint name="L_LEG4_KNEE_P" type="revolute">
    <origin rpy="0.0 0.0 0.0" xyz="0 0.0435 -0.35"/>
    <parent link="L_thigh"/>
    <child link="L_calf"/>
    <axis xyz="0.0 1.0 0.0"/>
    <limit effort="350" lower="0.174" upper="2.652" velocity="27.27"/>
    
  </joint>
  <link name="L_calf">
    <inertial>
      <origin rpy="0.0 0.0 0.0" xyz="0.023208952 0.00029598908 -0.14569598"/>
      <mass value="3.177945241"/>
      <inertia ixx="0.024290483" ixy="-9.253916e-05" ixz="0.0011860664" iyy="0.02455802" iyz="-0.00019133921" izz="0.0045686194"/>
    </inertial>
    <visual>
      <geometry>
        <mesh filename="meshes/mcalf.stl" scale="1e-3 1e-3 1e-3"/>
      </geometry>
    </visual>
    <collision>
      <origin rpy="0 0 0" xyz="0 0 0"/>
      <geometry>
        <mesh filename="meshes/mcalf.stl" scale="1e-3 1e-3 1e-3"/>
      </geometry>
    </collision>
  </link>
  <joint name="L_LEG5_ANKLE_P" type="revolute">
    <origin rpy="0.0 0.0 0.0" xyz="0 -0.005 -0.35"/>
    <parent link="L_calf"/>
    <child link="L_heel"/>
    <axis xyz="0.0 1.0 0.0"/>
    <limit effort="150.0" lower="-1.2217" upper="0.6458" velocity="33"/>
    
  </joint>
  <link name="L_heel">
    <inertial>
      <origin rpy="0.0 0.0 0.0" xyz="0.0028303307 0.0 0.0"/>
      <mass value="0.11492616"/>
      <inertia ixx="1.4387333e-05" ixy="0.0" ixz="0.0" iyy="2.2649914e-05" iyz="0.0" izz="3.0265224e-05"/>
    </inertial>
    <visual>
      <geometry>
        <mesh filename="meshes/heel.stl" scale="1e-3 1e-3 1e-3"/>
      </geometry>
    </visual>
    <collision>
      <origin rpy="0 0 0" xyz="0 0 0"/>
      <geometry>
        <mesh filename="meshes/heel.stl" scale="1e-3 1e-3 1e-3"/>
      </geometry>
    </collision>
  </link>
  <joint name="L_LEG6_ANKLE_R" type="revolute">
    <origin rpy="0.0 0.0 0.0" xyz="0 0 0"/>
    <parent link="L_heel"/>
    <child link="L_foot"/>
    <axis xyz="1.0 0.0 0.0"/>
    <limit effort="150.0" lower="-0.5236" upper="0.5236" velocity="33"/>
  </joint>
  <link name="L_foot">
    <inertial>
      <origin rpy="0.0 0.0 0.0" xyz="0.052443169 2.7716856e-05 -0.038116467"/>
      <mass value="1.14159198"/>
      <inertia ixx="0.0011434112" ixy="-4.7541301e-07" ixz="0.0001131398" iyy="0.0041371944" iyz="2.2942534e-07" izz="0.0045094953"/>
    </inertial>
    <visual>
      <geometry>
        <mesh filename="meshes/foot.stl" scale="1e-3 1e-3 1e-3"/>
      </geometry>
    </visual>
    <collision>
      <origin rpy="0.0 0.0 0.0" xyz="50e-3 0.0 -57e-3"/>
      <!-- <origin xyz="200e-3 0.0 -57e-3" rpy="0.0 0.0 0.0" /> -->
      <geometry>
        <box size="220e-3 80e-3 32e-3"/>
        <!-- <box size="0 80e-3 32e-3" /> -->
      </geometry>
    </collision>
  </link>
  <joint name="R_LEG1_HIP_Y" type="revolute">
    <origin rpy="0 0.7854 0" xyz="-0.108293 -0.075 -0.108293"/>
    <parent link="pelvis"/>
    <child link="R_buttock"/>
    <axis xyz="0.0 0.0 1.0"/>
    <limit effort="200" lower="-1.5708" upper="0.7854" velocity="22.19"/>
    
  </joint>
  <link name="R_buttock">
    <inertial>
      <origin rpy="0.0 0.0 0.0" xyz="0.0024957564 -1.2623423e-05 0.0046982699"/>
      <mass value="1.563261089"/>
      <inertia ixx="0.0019951068" ixy="-2.0533928e-07" ixz="-1.6097655e-05" iyy="0.0016946848" iyz="-1.8301724e-07" izz="0.0014133439"/>
    </inertial>
    <visual>
      <geometry>
        <mesh filename="meshes/buttock.stl" scale="1e-3 1e-3 1e-3"/>
      </geometry>
    </visual>
    <collision>
      <origin rpy="0 0 0" xyz="0 0 0"/>
      <geometry>
        <mesh filename="meshes/buttock.stl" scale="1e-3 1e-3 1e-3"/>
      </geometry>
    </collision>
  </link>
  <joint name="R_LEG2_HIP_R" type="revolute">
    <origin rpy="0.0 0.0 0.0" xyz="0 0 0"/>
    <parent link="R_buttock"/>
    <child link="R_leg"/>
    <axis xyz="1.0 0.0 0.0"/>
    <limit effort="100" lower="-0.7854" upper="0.7854" velocity="20.22"/>
  </joint>
  <link name="R_leg">
    <inertial>
      <origin rpy="0.0 0.0 0.0" xyz="0.14868123 -0.0035540022 0.00010724939"/>
      <mass value="4.113844972"/>
      <inertia ixx="0.011591155" ixy="4.1774824e-05" ixz="-9.045867e-05" iyy="0.023555436" iyz="-1.3727523e-05" izz="0.013497663"/>
    </inertial>
    <visual>
      <origin rpy="0 0 0" xyz="0 0 0"/>
      <geometry>
        <mesh filename="meshes/leg.stl" scale="1e-3 1e-3 1e-3"/>
      </geometry>
    </visual>
    <collision>
      <origin rpy="0 0 0" xyz="0 0 0"/>
      <geometry>
        <mesh filename="meshes/leg.stl" scale="1e-3 1e-3 1e-3"/>
      </geometry>
    </collision>
  </link>
  <joint name="R_LEG3_HIP_P" type="revolute">
    <origin rpy="0.0 -0.7854 0.0" xyz="0.1575 0 0"/>
    <parent link="R_leg"/>
    <child link="R_thigh"/>
    <axis xyz="0.0 1.0 0.0"/>
    <limit effort="350" lower="-2.3213" upper="1.3614" velocity="27.27"/>
  </joint>
  <link name="R_thigh">
    <inertial>
      <origin rpy="0.0 0.0 0.0" xyz="0.0022347405 -0.065808797 -0.065517537"/>
      <mass value="6.901348888"/>
      <inertia ixx="0.07943384" ixy="-3.6874363e-05" ixz="0.0037803199" iyy="0.088740509" iyz="0.0058211808" izz="0.020469118"/>
    </inertial>
    <visual>
      <geometry>
        <mesh filename="meshes/thigh.stl" scale="1e-3 1e-3 1e-3"/>
      </geometry>
    </visual>
    <collision>
      <origin rpy="0 0 0" xyz="0 0 0"/>
      <geometry>
        <mesh filename="meshes/thigh.stl" scale="1e-3 1e-3 1e-3"/>
      </geometry>
    </collision>
  </link>
  <joint name="R_LEG4_KNEE_P" type="revolute">
    <origin rpy="0.0 0.0 0.0" xyz="0 -0.0435 -0.35"/>
    <parent link="R_thigh"/>
    <child link="R_calf"/>
    <axis xyz="0.0 1.0 0.0"/>
    <limit effort="350" lower="0.174" upper="2.652" velocity="27.27"/>
  </joint>
  <link name="R_calf">
    <inertial>
      <origin rpy="0.0 0.0 0.0" xyz="0.023208952 -0.00029598908 -0.14569598"/>
      <mass value="3.177945241"/>
      <inertia ixx="0.024290483" ixy="9.253916e-05" ixz="0.0011860664" iyy="0.02455802" iyz="0.00019133921" izz="0.0045686194"/>
    </inertial>
    <visual>
      <geometry>
        <mesh filename="meshes/calf.stl" scale="1e-3 1e-3 1e-3"/>
      </geometry>
    </visual>
    <collision>
      <origin rpy="0 0 0" xyz="0 0 0"/>
      <geometry>
        <mesh filename="meshes/calf.stl" scale="1e-3 1e-3 1e-3"/>
      </geometry>
    </collision>
  </link>
  <joint name="R_LEG5_ANKLE_P" type="revolute">
    <origin rpy="0.0 0.0 0.0" xyz="0 0.005 -0.35"/>
    <parent link="R_calf"/>
    <child link="R_heel"/>
    <axis xyz="0.0 1.0 0.0"/>
    <limit effort="150.0" lower="-1.2217" upper="0.6458" velocity="33"/>
  </joint>
  <link name="R_heel">
    <inertial>
      <origin rpy="0.0 0.0 0.0" xyz="0.0028303307 0.0 0.0"/>
      <mass value="0.11492616"/>
      <inertia ixx="1.4387333e-05" ixy="0.0" ixz="0.0" iyy="2.2649914e-05" iyz="0.0" izz="3.0265224e-05"/>
    </inertial>
    <visual>
      <geometry>
        <mesh filename="meshes/heel.stl" scale="1e-3 1e-3 1e-3"/>
      </geometry>
    </visual>
    <collision>
      <origin rpy="0 0 0" xyz="0 0 0"/>
      <geometry>
        <mesh filename="meshes/heel.stl" scale="1e-3 1e-3 1e-3"/>
      </geometry>
    </collision>
  </link>
  <joint name="R_LEG6_ANKLE_R" type="revolute">
    <origin rpy="0.0 0.0 0.0" xyz="0 0 0"/>
    <parent link="R_heel"/>
    <child link="R_foot"/>
    <axis xyz="1.0 0.0 0.0"/>
    <limit effort="150.0" lower="-0.5236" upper="0.5236" velocity="33"/>
  </joint>
  <link name="R_foot">
    <inertial>
      <origin rpy="0.0 0.0 0.0" xyz="0.052443169 2.7716856e-05 -0.038116467"/>
      <mass value="1.14159198"/>
      <inertia ixx="0.0011434112" ixy="-4.7541301e-07" ixz="0.0001131398" iyy="0.0041371944" iyz="2.2942534e-07" izz="0.0045094953"/>
    </inertial>
    <visual>
      <geometry>
        <mesh filename="meshes/foot.stl" scale="1e-3 1e-3 1e-3"/>
      </geometry>
    </visual>
    <collision>
      <origin rpy="0.0 0.0 0.0" xyz="50e-3 0.0 -57e-3"/>
      <!-- <origin xyz="200e-3 0.0 -57e-3" rpy="0.0 0.0 0.0" /> -->
      <geometry>
        <box size="220e-3 80e-3 32e-3"/>
        <!-- <box size="0 80e-3 32e-3" /> -->
      </geometry>
    </collision>
  </link>
  <joint name="L_ARM1_SHOULDER_P" type="revolute">
    <origin rpy="-0.087 0.008 0.08722222" xyz="-0.04647802646 0.236711636842 0.357156560927"/>
    <parent link="trunk"/>
    <child link="L_clav"/>
    <axis xyz="0.0 1.0 0.0"/>
    <limit effort="102" lower="-3.1416" upper="1" velocity="4.71"/>
  </joint>
  <link name="L_clav">
    <inertial>
      <origin rpy="0.0 0.0 0.0" xyz="-0.0131 -0.00467 -0.00365"/>
      <mass value="1.594114926"/>
      <inertia ixx="0.00364" ixy="0.00254" ixz="-0.00295" iyy="0.547916019" iyz="0.000635" izz="0.015"/>
    </inertial>
    <visual>
      <origin rpy="-3.1415926 0 0" xyz="0 0 0"/>
      <geometry>
        <mesh filename="meshes/clav.stl" scale="1e-3 1e-3 1e-3"/>
      </geometry>
    </visual>
    <collision>
      <origin rpy="-1.5707963 0 0" xyz="-0.0117  0 0"/>
      <geometry>
        <cylinder length="0.13" radius="0.053"/>
      </geometry>
    </collision>
  </link>
  <joint name="L_ARM2_SHOULDER_R" type="revolute">
    <origin rpy="0.0 0.0 0.0" xyz="0 0 0"/>
    <parent link="L_clav"/>
    <child link="L_scapula"/>
    <axis xyz="1.0 0.0 0.0"/>
    <limit effort="102" lower="-0.175" upper="1.57" velocity="4.71"/>
    
  </joint>
  <link name="L_scapula">
    <inertial>
      <origin rpy="0.0 0.0 0.0" xyz="0.000165 0.00054 -0.111"/>
      <mass value="1.285576554"/>
      <inertia ixx="0.537702796" ixy="2.33e-06" ixz="3.53e-05" iyy="0.00522" iyz="-5.66e-05" izz="0.00195"/>
    </inertial>
    <visual>
      <origin rpy="0.0 0.0 0.0" xyz="0.0 0.0 0.0"/>
      <geometry>
        <mesh filename="meshes/scap.stl" scale="1e-3 1e-3 1e-3"/>
      </geometry>
    </visual>
    <collision>
      <origin rpy="0.0 0.0 0.0" xyz="0 0 -0.121"/>
      <geometry>
        <cylinder length="0.125" radius="0.06"/>
      </geometry>
    </collision>
  </link>
  <joint name="L_ARM3_SHOULDER_Y" type="revolute">
    <origin rpy="0.0 0.0 0.0" xyz="0 0 0"/>
    <parent link="L_scapula"/>
    <child link="L_uarm"/>
    <axis xyz="0.0 0.0 1.0"/>
    <limit effort="29" lower="-3.14" upper="3.14" velocity="8.12"/>
    
  </joint>
  <link name="L_uarm">
    <inertial>
      <origin rpy="0.0 0.0 0.0" xyz="5.4e-05 0.00362 -0.273"/>
      <mass value="1.14159198"/>
      <inertia ixx="0.00277" ixy="-2.31e-06" ixz="8.59e-07" iyy="0.00289" iyz="9.1e-06" izz="0.197260488"/>
    </inertial>
    <visual>
      <origin rpy="0 0 3.1415926" xyz="0 0 0"/>
      <geometry>
        <mesh filename="meshes/uarm.stl" scale="1e-3 1e-3 1e-3"/>
      </geometry>
    </visual>
    <collision>
      <origin rpy="0.0 0.0 0.0" xyz="0 0 -0.2445"/>
      <geometry>
        <cylinder length="0.105" radius="0.06"/>
      </geometry>
    </collision>
  </link>
  <joint name="L_ARM4_ELBOW_P" type="revolute">
    <origin rpy="0.0 0.0 0.0" xyz="0 0 -0.3012"/>
    <parent link="L_uarm"/>
    <child link="L_farmu"/>
    <axis xyz="0.0 1.0 0.0"/>
    <limit effort="29" lower="-1.919" upper="0.3" velocity="8.12"/>
  </joint>
  <link name="L_farmu">
    <inertial>
      <origin rpy="0.0 0.0 0.0" xyz="-0.000896 0.00121 -0.0832"/>
      <mass value="0.899903588"/>
      <inertia ixx="0.00181" ixy="-9.68e-06" ixz="2.67e-05" iyy="0.197858039" iyz="-6.85e-05" izz="0.00106"/>
    </inertial>
    <visual>
      <origin rpy="0 0 3.1415926" xyz="0 0 0"/>
      <geometry>
        <mesh filename="meshes/farmu.stl" scale="1e-3 1e-3 1e-3"/>
      </geometry>
    </visual>
    <collision>
      <origin rpy="0.0 0.0 0.0" xyz="0 0 -0.0579"/>
      <geometry>
        <cylinder length="0.11" radius="0.06"/>
      </geometry>
    </collision>
  </link>
  <joint name="L_ARM5_ELBOW_Y" type="revolute">
    <origin rpy="0.0 0.0 0.0" xyz="0 0 0"/>
    <parent link="L_farmu"/>
    <child link="L_farmd"/>
    <axis xyz="0.0 0.0 1.0"/>
    <limit effort="38.76" lower="-3.1416" upper="3.1416" velocity="14.37"/>
  </joint>
  <link name="L_farmd">
    <inertial>
      <origin rpy="0.0 0.0 0.0" xyz="0.000146818 -0.003847154 -0.23219571"/>
      <mass value="1.110738142"/>
      <inertia ixx="0.002762795" ixy="-1.0506e-05" ixz="-0.000167739" iyy="0.002773731" iyz="6.679e-05" izz="0.016538194"/>
    </inertial>
    <visual>
      <origin rpy="0 0 3.1415926" xyz="0 0 0"/>
      <geometry>
        <mesh filename="meshes/farmd.stl" scale="1e-3 1e-3 1e-3"/>
      </geometry>
    </visual>
    <collision>
      <origin rpy="0.0 0.0 0.0" xyz="0 0 -0.2079"/>
      <geometry>
        <cylinder length="0.18" radius="0.05"/>
      </geometry>
    </collision>
  </link>
  <joint name="L_ARM6_WRIST_R" type="revolute">
    <origin rpy="0.0 0.0 0.0" xyz="0 -0.01 -0.3232"/>
    <parent link="L_farmd"/>
    <child link="L_carp"/>
    <axis xyz="1.0 0.0 0.0"/>
    <limit effort="21.6" lower="-1.43" upper="0.79" velocity="8.81"/>
  </joint>
  <link name="L_carp">
    <inertial>
      <origin rpy="0.0 0.0 0.0" xyz="0 0.002745123 -0.013160251"/>
      <mass value="0.04337905"/>
      <inertia ixx="0.033956047" ixy="-0.0" ixz="0.0" iyy="4.136e-06" iyz="5.76e-07" izz="6.065e-06"/>
    </inertial>
    <visual>
      <origin rpy="0 0 3.1415926" xyz="0 0 0"/>
      <geometry>
        <mesh filename="meshes/carp.stl" scale="1e-3 1e-3 1e-3"/>
      </geometry>
    </visual>
    <collision>
      <origin rpy="0.0 0.0 0.0" xyz="0 0 0"/>
      <geometry>
        <box size="1e-3 1e-3 1e-3"/>
      </geometry>
    </collision>
  </link>
  <joint name="L_ARM7_WRIST_P" type="revolute">
    <origin rpy="0.0 0.0 0.0" xyz="0 0 -0.018"/>
    <parent link="L_carp"/>
    <child link="L_palm"/>
    <axis xyz="0.0 1.0 0.0"/>
    <limit effort="21.6" lower="-0.69" upper="0.81" velocity="8.81"/>
  </joint>
  <link name="L_palm">
    <inertial>
      <origin rpy="0.0 0.0 0.0" xyz="0.00464 0.00468 -0.0921"/>
      <mass value="0.990408177"/>
      <inertia ixx="0.004469629" ixy="0.000172787" ixz="0.000198391" iyy="0.038365503" iyz="-0.000237781" izz="0.001282267"/>
    </inertial>
    <visual>
      <origin rpy="0 0 0" xyz="0 0 0"/>
      <geometry>
        <mesh filename="meshes/mpalm.stl" scale="1e-3 1e-3 1e-3"/>
      </geometry>
    </visual>
    <collision>
      <origin rpy="0.0 0.0 0.0" xyz="0 0.01 -0.03675"/>
      <geometry>
        <cylinder length="0.0735" radius="30e-3"/>
      </geometry>
    </collision>
  </link>
  <joint name="L_palm_rf_joint" type="fixed">
    <origin rpy="-3.1415926 0.0 1.5707963" xyz="0 0.0099 -0.0525"/>
    <parent link="L_palm"/>
    <child link="L_palm_rf_link"/>
  </joint>
  <link name="L_palm_rf_link">
    <visual name="">
      <origin rpy="0.0 0.0 0.0" xyz="0.0 0.0 0.0"/>
      <geometry>
        <box size="0.01 0.01 0.01"/>
      </geometry>
    </visual>
    <collision>
      <origin rpy="0.0 0.0 0.0" xyz="0 0 0.068166"/>
      <geometry>
        <box size="40e-3 90e-3 0.09088800000000001"/>
      </geometry>
    </collision>
  </link>
  <joint name="L_pinky_finger_proximal_joint" type="fixed">
    <origin rpy="0.12211 0 0" xyz="-0.00227 -0.03431 0.11361"/>
    <parent link="L_palm_rf_link"/>
    <child link="L_pinky_finger_proximal"/>
    <axis xyz="0 1 0"/>
    <limit effort="1000" lower="-1.76686799448832" upper="-0.164555308610811" velocity="1"/>
  </joint>
  <link name="L_pinky_finger_proximal">
    <visual>
      <origin rpy="0 0 3.1415926" xyz="0 0 0"/>
      <geometry>
        <mesh filename="meshes/finger_proximal.stl" scale="1e-3 1e-3 1e-3"/>
      </geometry>
    </visual>
    <collision>
      <origin rpy="0.0 0.0 0.0" xyz="0 0 0"/>
      <geometry>
        <box size="1e-3 1e-3 1e-3"/>
      </geometry>
    </collision>
    <inertial>
      <origin rpy="0 0 0" xyz="-0.0024318988 3.328481e-07 0.010028137"/>
      <mass value="9.3522071e-09"/>
      <inertia ixx="1.1533308e-06" ixy="-1.327215e-11" ixz="2.5106055e-08" iyy="1.1732561e-06" iyz="2.2192538e-11" izz="5.6009882e-07"/>
    </inertial>
  </link>
  <joint name="L_pinky_finger_distal_joint" type="fixed">
    <origin rpy="0 0 0" xyz="0 0 0.0325"/>
    <parent link="L_pinky_finger_proximal"/>
    <child link="L_pinky_finger_distal"/>
    <axis xyz="0 1 0"/>
    <limit effort="1000" lower="0.33811" upper="3.58322" velocity="1"/>
    <mimic joint="L_pinky_finger_proximal_joint" multiplier="0.9845" offset="0.3017"/>
   
  </joint>
  <link name="L_pinky_finger_distal">
    <visual>
      <origin rpy="0 0 3.1415926" xyz="0 0 0"/>
      <geometry>
        <mesh filename="meshes/finger_distal.stl" scale="1e-3 1e-3 1e-3"/>
      </geometry>
    </visual>
    <collision>
      <origin rpy="0.0 0.0 0.0" xyz="0 0 0"/>
      <geometry>
        <box size="1e-3 1e-3 1e-3"/>
      </geometry>
    </collision>
    <inertial>
      <origin rpy="0 0 0" xyz="-0.0021920592 2.81739e-06 0.023240314"/>
      <mass value="1.2033694e-10"/>
      <inertia ixx="2.8856205e-06" ixy="-5.3997072e-11" ixz="-2.4954332e-07" iyy="2.8726183e-06" iyz="-9.9600212e-11" izz="3.6244504e-07"/>
    </inertial>
  </link>
  <joint name="L_ring_finger_proximal_joint" type="fixed">
    <origin rpy="0.06108 0 0" xyz="-0.00227 -0.01395 0.11541"/>
    <parent link="L_palm_rf_link"/>
    <child link="L_ring_finger_proximal"/>
    <axis xyz="0 1 0"/>
    <limit effort="1000" lower="-1.76686799448832" upper="-0.164555308610811" velocity="1"/>
   
  </joint>
  <link name="L_ring_finger_proximal">
    <visual>
      <origin rpy="0 0 3.1415926" xyz="0 0 0"/>
      <geometry>
        <mesh filename="meshes/finger_proximal.stl" scale="1e-3 1e-3 1e-3"/>
      </geometry>
    </visual>
    <collision>
      <origin rpy="0.0 0.0 0.0" xyz="0 0 0"/>
      <geometry>
        <box size="1e-3 1e-3 1e-3"/>
      </geometry>
    </collision>
    <inertial>
      <origin rpy="0 0 0" xyz="-0.0024318988 3.328481e-07 0.010028137"/>
      <mass value="9.3522071e-09"/>
      <inertia ixx="1.1533308e-06" ixy="-1.327215e-11" ixz="2.5106055e-08" iyy="1.1732561e-06" iyz="2.2192538e-11" izz="5.6009882e-07"/>
    </inertial>
  </link>
  <joint name="L_ring_finger_distal_joint" type="fixed">
    <origin rpy="0 0 0" xyz="0 0 0.0325"/>
    <parent link="L_ring_finger_proximal"/>
    <child link="L_ring_finger_distal"/>
    <axis xyz="0 1 0"/>
    <limit effort="1000" lower="0.33811" upper="3.58322" velocity="1"/>
    <mimic joint="L_ring_finger_proximal_joint" multiplier="0.9845" offset="0.3017"/>
   
  </joint>
  <link name="L_ring_finger_distal">
    <visual>
      <origin rpy="0 0 3.1415926" xyz="0 0 0"/>
      <geometry>
        <mesh filename="meshes/finger_distal.stl" scale="1e-3 1e-3 1e-3"/>
      </geometry>
    </visual>
    <collision>
      <origin rpy="0.0 0.0 0.0" xyz="0 0 0"/>
      <geometry>
        <box size="1e-3 1e-3 1e-3"/>
      </geometry>
    </collision>
    <inertial>
      <origin rpy="0 0 0" xyz="-0.0021920592 2.81739e-06 0.023240314"/>
      <mass value="1.2033694e-10"/>
      <inertia ixx="2.8856205e-06" ixy="-5.3997072e-11" ixz="-2.4954332e-07" iyy="2.8726183e-06" iyz="-9.9600212e-11" izz="3.6244504e-07"/>
    </inertial>
  </link>
  <joint name="L_middle_finger_proximal_joint" type="fixed">
    <origin rpy="0 0 0" xyz="-0.00227 0.00675 0.1161"/>
    <parent link="L_palm_rf_link"/>
    <child link="L_middle_finger_proximal"/>
    <axis xyz="0 1 0"/>
    <limit effort="1000" lower="-1.76686799448832" upper="-0.164555308610811" velocity="1"/>
   
  </joint>
  <link name="L_middle_finger_proximal">
    <visual>
      <origin rpy="0 0 3.1415926" xyz="0 0 0"/>
      <geometry>
        <mesh filename="meshes/finger_proximal.stl" scale="1e-3 1e-3 1e-3"/>
      </geometry>
    </visual>
    <collision>
      <origin rpy="0.0 0.0 0.0" xyz="0 0 0"/>
      <geometry>
        <box size="1e-3 1e-3 1e-3"/>
      </geometry>
    </collision>
    <inertial>
      <origin rpy="0 0 0" xyz="-0.0024318988 3.328481e-07 0.010028137"/>
      <mass value="9.3522071e-09"/>
      <inertia ixx="1.1533308e-06" ixy="-1.327215e-11" ixz="2.5106055e-08" iyy="1.1732561e-06" iyz="2.2192538e-11" izz="5.6009882e-07"/>
    </inertial>
  </link>
  <joint name="L_middle_finger_distal_joint" type="fixed">
    <origin rpy="0 0 0" xyz="0 0 0.0325"/>
    <parent link="L_middle_finger_proximal"/>
    <child link="L_middle_finger_distal"/>
    <axis xyz="0 1 0"/>
    <limit effort="1000" lower="0.33811" upper="3.58322" velocity="1"/>
    <mimic joint="L_middle_finger_proximal_joint" multiplier="0.9845" offset="0.3017"/>
   
  </joint>
  <link name="L_middle_finger_distal">
    <visual>
      <origin rpy="0 0 3.1415926" xyz="0 0 0"/>
      <geometry>
        <mesh filename="meshes/finger_distal.stl" scale="1e-3 1e-3 1e-3"/>
      </geometry>
    </visual>
    <collision>
      <origin rpy="0.0 0.0 0.0" xyz="0 0 0"/>
      <geometry>
        <box size="1e-3 1e-3 1e-3"/>
      </geometry>
    </collision>
    <inertial>
      <origin rpy="0 0 0" xyz="-0.0021920592 2.81739e-06 0.023240314"/>
      <mass value="1.2033694e-10"/>
      <inertia ixx="2.8856205e-06" ixy="-5.3997072e-11" ixz="-2.4954332e-07" iyy="2.8726183e-06" iyz="-9.9600212e-11" izz="3.6244504e-07"/>
    </inertial>
  </link>
  <joint name="L_index_finger_proximal_joint" type="fixed">
    <origin rpy="-0.05236 0 0" xyz="-0.00227 0.02766 0.11556"/>
    <parent link="L_palm_rf_link"/>
    <child link="L_index_finger_proximal"/>
    <axis xyz="0 1 0"/>
    <limit effort="1000" lower="-1.76686799448832" upper="-0.164555308610811" velocity="1"/>
   
  </joint>
  <link name="L_index_finger_proximal">
    <visual>
      <origin rpy="0 0 3.1415926" xyz="0 0 0"/>
      <geometry>
        <mesh filename="meshes/finger_proximal.stl" scale="1e-3 1e-3 1e-3"/>
      </geometry>
    </visual>
    <collision>
      <origin rpy="0.0 0.0 0.0" xyz="0 0 0"/>
      <geometry>
        <box size="1e-3 1e-3 1e-3"/>
      </geometry>
    </collision>
    <inertial>
      <origin rpy="0 0 0" xyz="-0.0024318988 3.328481e-07 0.010028137"/>
      <mass value="9.3522071e-09"/>
      <inertia ixx="1.1533308e-06" ixy="-1.327215e-11" ixz="2.5106055e-08" iyy="1.1732561e-06" iyz="2.2192538e-11" izz="5.6009882e-07"/>
    </inertial>
  </link>
  <joint name="L_index_finger_distal_joint" type="fixed">
    <origin rpy="0 0 0" xyz="0 0 0.0325"/>
    <parent link="L_index_finger_proximal"/>
    <child link="L_index_finger_distal"/>
    <axis xyz="0 1 0"/>
    <limit effort="1000" lower="0.33811" upper="3.58322" velocity="1"/>
    <mimic joint="L_index_finger_proximal_joint" multiplier="0.9845" offset="0.3017"/>
   
  </joint>
  <link name="L_index_finger_distal">
    <visual>
      <origin rpy="0 0 3.1415926" xyz="0 0 0"/>
      <geometry>
        <mesh filename="meshes/finger_distal.stl" scale="1e-3 1e-3 1e-3"/>
      </geometry>
    </visual>
    <collision>
      <origin rpy="0.0 0.0 0.0" xyz="0 0 0"/>
      <geometry>
        <box size="1e-3 1e-3 1e-3"/>
      </geometry>
    </collision>
    <inertial>
      <origin rpy="0 0 0" xyz="-0.0021920592 2.81739e-06 0.023240314"/>
      <mass value="1.2033694e-10"/>
      <inertia ixx="2.8856205e-06" ixy="-5.3997072e-11" ixz="-2.4954332e-07" iyy="2.8726183e-06" iyz="-9.9600212e-11" izz="3.6244504e-07"/>
    </inertial>
  </link>
  <joint name="L_thumb_opp_joint" type="fixed">
    <origin rpy="0 0 0" xyz="-0.021 0.02025 0.03885"/>
    <parent link="L_palm_rf_link"/>
    <child link="L_thumb_opp"/>
    <axis xyz="0 0 1"/>
    <limit effort="1000" lower="1.7622963" upper="3.0968963" velocity="1"/>
   
  </joint>
  <link name="L_thumb_opp">
    <inertial>
      <origin rpy="0.0 0.0 0.0" xyz="-0.0043445795 0.00073516028 0.00092114437"/>
      <mass value="4.5684539e-08"/>
      <inertia ixx="1.2807232e-07" ixy="-2.6031726e-08" ixz="9.2990531e-09" iyy="2.0994928e-07" iyz="2.3599758e-09" izz="1.8089779e-07"/>
    </inertial>
    <visual>
      <origin rpy="0 0 0" xyz="0 0 0"/>
      <geometry>
        <mesh filename="meshes/mthumb_opp.stl" scale="1e-3 1e-3 1e-3"/>
      </geometry>
    </visual>
    <collision>
      <origin rpy="0.0 0.0 0.0" xyz="0.0 0.0 0.0"/>
      <geometry>
        <box size="0.001 0.001 0.001"/>
      </geometry>
    </collision>
  </link>
  <joint name="L_thumb_proximal_joint" type="fixed">
    <origin rpy="0 0 0" xyz="0.011 0 0"/>
    <parent link="L_thumb_opp"/>
    <child link="L_thumb_proximal"/>
    <axis xyz="0 1 0"/>
    <limit effort="1000" lower="0.31536831160939" upper="0.957365354375099" velocity="1"/>
   
  </joint>
  <link name="L_thumb_proximal">
    <visual>
      <origin rpy="0 0 0" xyz="0 0 0"/>
      <geometry>
        <mesh filename="meshes/thumb_proximal.stl" scale="1e-3 1e-3 1e-3"/>
      </geometry>
    </visual>
    <collision>
      <origin rpy="0.0 0.0 0.0" xyz="0 0 0"/>
      <geometry>
        <box size="1e-3 1e-3 1e-3"/>
      </geometry>
    </collision>
    <inertial>
      <origin rpy="0.0 0.0 0.0" xyz="0.0037146239 0.0 0.025714396"/>
      <mass value="4.8359764e-07"/>
      <inertia ixx="1.1564874e-05" ixy="0.0" ixz="9.8057604e-07" iyy="1.2950704e-05" iyz="0.0" izz="4.7469757e-06"/>
    </inertial>
  </link>
  <joint name="L_thumb_middle_joint" type="fixed">
    <origin rpy="0 0 0" xyz="0 0 0.05572"/>
    <parent link="L_thumb_proximal"/>
    <child link="L_thumb_middle"/>
    <axis xyz="0 1 0"/>
    <mimic joint="L_thumb_proximal_joint" multiplier="1.257" offset="-1.192"/>
    <limit effort="1000" lower="0" upper="1" velocity="1"/>
   
  </joint>
  <link name="L_thumb_middle">
    <visual>
      <origin rpy="0 0 0" xyz="0 0 0"/>
      <geometry>
        <mesh filename="meshes/thumb_middle.stl" scale="1e-3 1e-3 1e-3"/>
      </geometry>
    </visual>
    <collision>
      <origin rpy="0.0 0.0 0.0" xyz="0 0 0"/>
      <geometry>
        <box size="1e-3 1e-3 1e-3"/>
      </geometry>
    </collision>
    <inertial>
      <origin rpy="0.0 0.0 0.0" xyz="0.0034051517 0 0.010727105"/>
      <mass value="7.5745038e-08"/>
      <inertia ixx="6.6016669e-07" ixy="0.0" ixz="-1.9329706e-08" iyy="6.3533864e-07" iyz="0.0" izz="6.546447e-07"/>
    </inertial>
  </link>
  <joint name="L_thumb_distal_joint" type="fixed">
    <origin rpy="0 0 0" xyz="0 0 0.02305"/>
    <parent link="L_thumb_middle"/>
    <child link="L_thumb_distal"/>
    <axis xyz="0 1 0"/>
    <mimic joint="L_thumb_proximal_joint" multiplier="1.009" offset="-0.85"/>
    <limit effort="1000" lower="0" upper="1" velocity="1"/>
   
  </joint>
  <link name="L_thumb_distal">
    <visual>
      <origin rpy="0 0 0" xyz="0 0 0"/>
      <geometry>
        <mesh filename="meshes/thumb_distal.stl" scale="1e-3 1e-3 1e-3"/>
      </geometry>
    </visual>
    <collision>
      <origin rpy="0.0 0.0 0.0" xyz="0 0 0"/>
      <geometry>
        <box size="1e-3 1e-3 1e-3"/>
      </geometry>
    </collision>
    <inertial>
      <origin rpy="0.0 0.0 0.0" xyz="0.00058212386 4.4266405e-06 0.014881067"/>
      <mass value="8.7566711e-07"/>
      <inertia ixx="1.0204087e-06" ixy="-8.9029655e-11" ixz="7.0098201e-08" iyy="9.9146034e-07" iyz="1.7085357e-10" izz="3.1951504e-07"/>
    </inertial>
  </link>
  <joint name="R_ARM1_SHOULDER_P" type="revolute">
    <origin rpy="0.087 0.008 -0.08722222" xyz="-0.04647802646 -0.236711636842 0.357156560927"/>
    <parent link="trunk"/>
    <child link="R_clav"/>
    <axis xyz="0.0 1.0 0.0"/>
    <limit effort="102" lower="-3.1416" upper="1" velocity="4.71"/>
  </joint>
  <link name="R_clav">
    <inertial>
      <origin rpy="0.0 0.0 0.0" xyz="-0.0131 0.00467 -0.00365"/>
      <mass value="1.594114926"/>
      <inertia ixx="0.00364" ixy="-0.00254" ixz="-0.00295" iyy="0.547916019" iyz="-0.000635" izz="0.015"/>
    </inertial>
    <visual>
      <origin rpy="0 0 0" xyz="0 0 0"/>
      <geometry>
        <mesh filename="meshes/clav.stl" scale="1e-3 1e-3 1e-3"/>
      </geometry>
    </visual>
    <collision>
      <origin rpy="-1.5707963 0 0" xyz="-0.0117  0 0"/>
      <geometry>
        <cylinder length="0.13" radius="0.053"/>
      </geometry>
    </collision>
  </link>
  <joint name="R_ARM2_SHOULDER_R" type="revolute">
    <origin rpy="0.0 0.0 0.0" xyz="0 0 0"/>
    <parent link="R_clav"/>
    <child link="R_scapula"/>
    <axis xyz="1.0 0.0 0.0"/>
    <limit effort="102" lower="-1.57" upper="0.175" velocity="4.71"/>
  </joint>
  <link name="R_scapula">
    <inertial>
      <origin rpy="0.0 0.0 0.0" xyz="0.000165 -0.00054 -0.111"/>
      <mass value="1.285576554"/>
      <inertia ixx="0.537702796" ixy="-2.33e-06" ixz="3.53e-05" iyy="0.00522" iyz="5.66e-05" izz="0.00195"/>
    </inertial>
    <visual>
      <origin rpy="0.0 0.0 0.0" xyz="0.0 0.0 0.0"/>
      <geometry>
        <mesh filename="meshes/scap.stl" scale="1e-3 1e-3 1e-3"/>
      </geometry>
    </visual>
    <collision>
      <origin rpy="0.0 0.0 0.0" xyz="0 0 -0.121"/>
      <geometry>
        <cylinder length="0.125" radius="0.06"/>
      </geometry>
    </collision>
  </link>
  <joint name="R_ARM3_SHOULDER_Y" type="revolute">
    <origin rpy="0.0 0.0 0.0" xyz="0 0 0"/>
    <parent link="R_scapula"/>
    <child link="R_uarm"/>
    <axis xyz="0.0 0.0 1.0"/>
    <limit effort="29" lower="-3.14" upper="3.14" velocity="8.12"/>
  </joint>
  <link name="R_uarm">
    <inertial>
      <origin rpy="0.0 0.0 0.0" xyz="5.4e-05 -0.00362 -0.273"/>
      <mass value="1.14159198"/>
      <inertia ixx="0.00277" ixy="2.31e-06" ixz="8.59e-07" iyy="0.00289" iyz="-9.1e-06" izz="0.197260488"/>
    </inertial>
    <visual>
      <origin rpy="0 0 0" xyz="0 0 0"/>
      <geometry>
        <mesh filename="meshes/uarm.stl" scale="1e-3 1e-3 1e-3"/>
      </geometry>
    </visual>
    <collision>
      <origin rpy="0.0 0.0 0.0" xyz="0 0 -0.2445"/>
      <geometry>
        <cylinder length="0.105" radius="0.06"/>
      </geometry>
    </collision>
  </link>
  <joint name="R_ARM4_ELBOW_P" type="revolute">
    <origin rpy="0.0 0.0 0.0" xyz="0 0 -0.3012"/>
    <parent link="R_uarm"/>
    <child link="R_farmu"/>
    <axis xyz="0.0 1.0 0.0"/>
    <limit effort="29" lower="-1.919" upper="0.3" velocity="8.12"/>
  </joint>
  <link name="R_farmu">
    <inertial>
      <origin rpy="0.0 0.0 0.0" xyz="-0.000896 -0.00121 -0.0832"/>
      <mass value="0.899903588"/>
      <inertia ixx="0.00181" ixy="9.68e-06" ixz="2.67e-05" iyy="0.197858039" iyz="6.85e-05" izz="0.00106"/>
    </inertial>
    <visual>
      <origin rpy="0 0 0" xyz="0 0 0"/>
      <geometry>
        <mesh filename="meshes/farmu.stl" scale="1e-3 1e-3 1e-3"/>
      </geometry>
    </visual>
    <collision>
      <origin rpy="0.0 0.0 0.0" xyz="0 0 -0.0579"/>
      <geometry>
        <cylinder length="0.11" radius="0.06"/>
      </geometry>
    </collision>
  </link>
  <joint name="R_ARM5_ELBOW_Y" type="revolute">
    <origin rpy="0.0 0.0 0.0" xyz="0 0 0"/>
    <parent link="R_farmu"/>
    <child link="R_farmd"/>
    <axis xyz="0.0 0.0 1.0"/>
    <limit effort="38.76" lower="-3.1416" upper="3.1416" velocity="14.37"/>
  </joint>
  <link name="R_farmd">
    <inertial>
      <origin rpy="0.0 0.0 0.0" xyz="0.000146818 0.003847154 -0.23219571"/>
      <mass value="1.110738142"/>
      <inertia ixx="0.002762795" ixy="1.0506e-05" ixz="-0.000167739" iyy="0.002773731" iyz="-6.679e-05" izz="0.016538194"/>
    </inertial>
    <visual>
      <origin rpy="0 0 0" xyz="0 0 0"/>
      <geometry>
        <mesh filename="meshes/farmd.stl" scale="1e-3 1e-3 1e-3"/>
      </geometry>
    </visual>
    <collision>
      <origin rpy="0.0 0.0 0.0" xyz="0 0 -0.2079"/>
      <geometry>
        <cylinder length="0.18" radius="0.05"/>
      </geometry>
    </collision>
  </link>
  <joint name="R_ARM6_WRIST_R" type="revolute">
    <origin rpy="0.0 0.0 0.0" xyz="0 0.01 -0.3232"/>
    <parent link="R_farmd"/>
    <child link="R_carp"/>
    <axis xyz="1.0 0.0 0.0"/>
    <limit effort="21.6" lower="-0.79" upper="1.43" velocity="8.81"/>
  </joint>
  <link name="R_carp">
    <inertial>
      <origin rpy="0.0 0.0 0.0" xyz="0 -0.002745123 -0.013160251"/>
      <mass value="0.04337905"/>
      <inertia ixx="0.033956047" ixy="0.0" ixz="0.0" iyy="4.136e-06" iyz="-5.76e-07" izz="6.065e-06"/>
    </inertial>
    <visual>
      <origin rpy="0 0 0" xyz="0 0 0"/>
      <geometry>
        <mesh filename="meshes/carp.stl" scale="1e-3 1e-3 1e-3"/>
      </geometry>
    </visual>
    <collision>
      <origin rpy="0.0 0.0 0.0" xyz="0 0 0"/>
      <geometry>
        <box size="1e-3 1e-3 1e-3"/>
      </geometry>
    </collision>
  </link>
  <joint name="R_ARM7_WRIST_P" type="revolute">
    <origin rpy="0.0 0.0 0.0" xyz="0 0 -0.018"/>
    <parent link="R_carp"/>
    <child link="R_palm"/>
    <axis xyz="0.0 1.0 0.0"/>
    <limit effort="21.6" lower="-0.69" upper="0.81" velocity="8.81"/>
  </joint>
  <link name="R_palm">
    <inertial>
      <origin rpy="0.0 0.0 0.0" xyz="0.00464 -0.00468 -0.0921"/>
      <mass value="0.990408177"/>
      <inertia ixx="0.004469629" ixy="-0.000172787" ixz="0.000198391" iyy="0.038365503" iyz="0.000237781" izz="0.001282267"/>
    </inertial>
    <visual>
      <origin rpy="0 0 0" xyz="0 0 0"/>
      <geometry>
        <mesh filename="meshes/palm.stl" scale="1e-3 1e-3 1e-3"/>
      </geometry>
    </visual>
    <collision>
      <origin rpy="0.0 0.0 0.0" xyz="0 -0.01 -0.03675"/>
      <geometry>
        <cylinder length="0.0735" radius="30e-3"/>
      </geometry>
    </collision>
  </link>
  <joint name="R_palm_rf_joint" type="fixed">
    <origin rpy="-3.1415926 0.0 1.5707963" xyz="0 -0.0099 -0.0525"/>
    <parent link="R_palm"/>
    <child link="R_palm_rf_link"/>
  </joint>
  <link name="R_palm_rf_link">
    <visual name="">
      <origin rpy="0.0 0.0 0.0" xyz="0.0 0.0 0.0"/>
      <geometry>
        <box size="0.01 0.01 0.01"/>
      </geometry>
    </visual>
    <collision>
      <origin rpy="0.0 0.0 0.0" xyz="0 0 0.068166"/>
      <geometry>
        <box size="40e-3 90e-3 0.09088800000000001"/>
      </geometry>
    </collision>
  </link>
  <joint name="R_pinky_finger_proximal_joint" type="fixed">
    <origin rpy="0.12211 0 0" xyz="0.00227 -0.03431 0.11361"/>
    <parent link="R_palm_rf_link"/>
    <child link="R_pinky_finger_proximal"/>
    <axis xyz="0 1 0"/>
    <limit effort="1000" lower="0.164555308610811" upper="1.76686799448832" velocity="1"/>
   
  </joint>
  <link name="R_pinky_finger_proximal">
    <visual>
      <origin rpy="0 0 0" xyz="0 0 0"/>
      <geometry>
        <mesh filename="meshes/finger_proximal.stl" scale="1e-3 1e-3 1e-3"/>
      </geometry>
    </visual>
    <collision>
      <origin rpy="0.0 0.0 0.0" xyz="0 0 0"/>
      <geometry>
        <box size="1e-3 1e-3 1e-3"/>
      </geometry>
    </collision>
    <inertial>
      <origin rpy="0 0 0" xyz="-0.0024318988 3.328481e-07 0.010028137"/>
      <mass value="9.3522071e-09"/>
      <inertia ixx="1.1533308e-06" ixy="-1.327215e-11" ixz="2.5106055e-08" iyy="1.1732561e-06" iyz="2.2192538e-11" izz="5.6009882e-07"/>
    </inertial>
  </link>
  <joint name="R_pinky_finger_distal_joint" type="fixed">
    <origin rpy="0 0 0" xyz="0 0 0.0325"/>
    <parent link="R_pinky_finger_proximal"/>
    <child link="R_pinky_finger_distal"/>
    <axis xyz="0 1 0"/>
    <limit effort="1000" lower="0.33811" upper="3.58322" velocity="1"/>
    <mimic joint="R_pinky_finger_proximal_joint" multiplier="0.9845" offset="-0.3017"/>
   
  </joint>
  <link name="R_pinky_finger_distal">
    <visual>
      <origin rpy="0 0 0" xyz="0 0 0"/>
      <geometry>
        <mesh filename="meshes/finger_distal.stl" scale="1e-3 1e-3 1e-3"/>
      </geometry>
    </visual>
    <collision>
      <origin rpy="0.0 0.0 0.0" xyz="0 0 0"/>
      <geometry>
        <box size="1e-3 1e-3 1e-3"/>
      </geometry>
    </collision>
    <inertial>
      <origin rpy="0 0 0" xyz="-0.0021920592 2.81739e-06 0.023240314"/>
      <mass value="1.2033694e-10"/>
      <inertia ixx="2.8856205e-06" ixy="-5.3997072e-11" ixz="-2.4954332e-07" iyy="2.8726183e-06" iyz="-9.9600212e-11" izz="3.6244504e-07"/>
    </inertial>
  </link>
  <joint name="R_ring_finger_proximal_joint" type="fixed">
    <origin rpy="0.06108 0 0" xyz="0.00227 -0.01395 0.11541"/>
    <parent link="R_palm_rf_link"/>
    <child link="R_ring_finger_proximal"/>
    <axis xyz="0 1 0"/>
    <limit effort="1000" lower="0.164555308610811" upper="1.76686799448832" velocity="1"/>
   
  </joint>
  <link name="R_ring_finger_proximal">
    <visual>
      <origin rpy="0 0 0" xyz="0 0 0"/>
      <geometry>
        <mesh filename="meshes/finger_proximal.stl" scale="1e-3 1e-3 1e-3"/>
      </geometry>
    </visual>
    <collision>
      <origin rpy="0.0 0.0 0.0" xyz="0 0 0"/>
      <geometry>
        <box size="1e-3 1e-3 1e-3"/>
      </geometry>
    </collision>
    <inertial>
      <origin rpy="0 0 0" xyz="-0.0024318988 3.328481e-07 0.010028137"/>
      <mass value="9.3522071e-09"/>
      <inertia ixx="1.1533308e-06" ixy="-1.327215e-11" ixz="2.5106055e-08" iyy="1.1732561e-06" iyz="2.2192538e-11" izz="5.6009882e-07"/>
    </inertial>
  </link>
  <joint name="R_ring_finger_distal_joint" type="fixed">
    <origin rpy="0 0 0" xyz="0 0 0.0325"/>
    <parent link="R_ring_finger_proximal"/>
    <child link="R_ring_finger_distal"/>
    <axis xyz="0 1 0"/>
    <limit effort="1000" lower="0.33811" upper="3.58322" velocity="1"/>
    <mimic joint="R_ring_finger_proximal_joint" multiplier="0.9845" offset="-0.3017"/>
   
  </joint>
  <link name="R_ring_finger_distal">
    <visual>
      <origin rpy="0 0 0" xyz="0 0 0"/>
      <geometry>
        <mesh filename="meshes/finger_distal.stl" scale="1e-3 1e-3 1e-3"/>
      </geometry>
    </visual>
    <collision>
      <origin rpy="0.0 0.0 0.0" xyz="0 0 0"/>
      <geometry>
        <box size="1e-3 1e-3 1e-3"/>
      </geometry>
    </collision>
    <inertial>
      <origin rpy="0 0 0" xyz="-0.0021920592 2.81739e-06 0.023240314"/>
      <mass value="1.2033694e-10"/>
      <inertia ixx="2.8856205e-06" ixy="-5.3997072e-11" ixz="-2.4954332e-07" iyy="2.8726183e-06" iyz="-9.9600212e-11" izz="3.6244504e-07"/>
    </inertial>
  </link>
  <joint name="R_middle_finger_proximal_joint" type="fixed">
    <origin rpy="0 0 0" xyz="0.00227 0.00675 0.1161"/>
    <parent link="R_palm_rf_link"/>
    <child link="R_middle_finger_proximal"/>
    <axis xyz="0 1 0"/>
    <limit effort="1000" lower="0.164555308610811" upper="1.76686799448832" velocity="1"/>
   
  </joint>
  <link name="R_middle_finger_proximal">
    <visual>
      <origin rpy="0 0 0" xyz="0 0 0"/>
      <geometry>
        <mesh filename="meshes/finger_proximal.stl" scale="1e-3 1e-3 1e-3"/>
      </geometry>
    </visual>
    <collision>
      <origin rpy="0.0 0.0 0.0" xyz="0 0 0"/>
      <geometry>
        <box size="1e-3 1e-3 1e-3"/>
      </geometry>
    </collision>
    <inertial>
      <origin rpy="0 0 0" xyz="-0.0024318988 3.328481e-07 0.010028137"/>
      <mass value="9.3522071e-09"/>
      <inertia ixx="1.1533308e-06" ixy="-1.327215e-11" ixz="2.5106055e-08" iyy="1.1732561e-06" iyz="2.2192538e-11" izz="5.6009882e-07"/>
    </inertial>
  </link>
  <joint name="R_middle_finger_distal_joint" type="fixed">
    <origin rpy="0 0 0" xyz="0 0 0.0325"/>
    <parent link="R_middle_finger_proximal"/>
    <child link="R_middle_finger_distal"/>
    <axis xyz="0 1 0"/>
    <limit effort="1000" lower="0.33811" upper="3.58322" velocity="1"/>
    <mimic joint="R_middle_finger_proximal_joint" multiplier="0.9845" offset="-0.3017"/>
   
  </joint>
  <link name="R_middle_finger_distal">
    <visual>
      <origin rpy="0 0 0" xyz="0 0 0"/>
      <geometry>
        <mesh filename="meshes/finger_distal.stl" scale="1e-3 1e-3 1e-3"/>
      </geometry>
    </visual>
    <collision>
      <origin rpy="0.0 0.0 0.0" xyz="0 0 0"/>
      <geometry>
        <box size="1e-3 1e-3 1e-3"/>
      </geometry>
    </collision>
    <inertial>
      <origin rpy="0 0 0" xyz="-0.0021920592 2.81739e-06 0.023240314"/>
      <mass value="1.2033694e-10"/>
      <inertia ixx="2.8856205e-06" ixy="-5.3997072e-11" ixz="-2.4954332e-07" iyy="2.8726183e-06" iyz="-9.9600212e-11" izz="3.6244504e-07"/>
    </inertial>
  </link>
  <joint name="R_index_finger_proximal_joint" type="fixed">
    <origin rpy="-0.05236 0 0" xyz="0.00227 0.02766 0.11556"/>
    <parent link="R_palm_rf_link"/>
    <child link="R_index_finger_proximal"/>
    <axis xyz="0 1 0"/>
    <limit effort="1000" lower="0.164555308610811" upper="1.76686799448832" velocity="1"/>
   
  </joint>
  <link name="R_index_finger_proximal">
    <visual>
      <origin rpy="0 0 0" xyz="0 0 0"/>
      <geometry>
        <mesh filename="meshes/finger_proximal.stl" scale="1e-3 1e-3 1e-3"/>
      </geometry>
    </visual>
    <collision>
      <origin rpy="0.0 0.0 0.0" xyz="0 0 0"/>
      <geometry>
        <box size="1e-3 1e-3 1e-3"/>
      </geometry>
    </collision>
    <inertial>
      <origin rpy="0 0 0" xyz="-0.0024318988 3.328481e-07 0.010028137"/>
      <mass value="9.3522071e-09"/>
      <inertia ixx="1.1533308e-06" ixy="-1.327215e-11" ixz="2.5106055e-08" iyy="1.1732561e-06" iyz="2.2192538e-11" izz="5.6009882e-07"/>
    </inertial>
  </link>
  <joint name="R_index_finger_distal_joint" type="fixed">
    <origin rpy="0 0 0" xyz="0 0 0.0325"/>
    <parent link="R_index_finger_proximal"/>
    <child link="R_index_finger_distal"/>
    <axis xyz="0 1 0"/>
    <limit effort="1000" lower="0.33811" upper="3.58322" velocity="1"/>
    <mimic joint="R_index_finger_proximal_joint" multiplier="0.9845" offset="-0.3017"/>
   
  </joint>
  <link name="R_index_finger_distal">
    <visual>
      <origin rpy="0 0 0" xyz="0 0 0"/>
      <geometry>
        <mesh filename="meshes/finger_distal.stl" scale="1e-3 1e-3 1e-3"/>
      </geometry>
    </visual>
    <collision>
      <origin rpy="0.0 0.0 0.0" xyz="0 0 0"/>
      <geometry>
        <box size="1e-3 1e-3 1e-3"/>
      </geometry>
    </collision>
    <inertial>
      <origin rpy="0 0 0" xyz="-0.0021920592 2.81739e-06 0.023240314"/>
      <mass value="1.2033694e-10"/>
      <inertia ixx="2.8856205e-06" ixy="-5.3997072e-11" ixz="-2.4954332e-07" iyy="2.8726183e-06" iyz="-9.9600212e-11" izz="3.6244504e-07"/>
    </inertial>
  </link>
  <joint name="R_thumb_opp_joint" type="fixed">
    <origin rpy="0 0 0" xyz="0.021 0.02025 0.03885"/>
    <parent link="R_palm_rf_link"/>
    <child link="R_thumb_opp"/>
    <axis xyz="0 0 1"/>
    <limit effort="1000" lower="0.1915" upper="1.5261" velocity="1"/>
   
  </joint>
  <link name="R_thumb_opp">
    <inertial>
      <origin rpy="0.0 0.0 0.0" xyz="0.0043445795 0.00073516028 0.00092114437"/>
      <mass value="4.5684539e-08"/>
      <inertia ixx="1.2807232e-07" ixy="2.6031726e-08" ixz="-9.2990531e-09" iyy="2.0994928e-07" iyz="2.3599758e-09" izz="1.8089779e-07"/>
    </inertial>
    <visual>
      <origin rpy="0 0 0" xyz="0 0 0"/>
      <geometry>
        <mesh filename="meshes/thumb_opposition.stl" scale="1e-3 1e-3 1e-3"/>
      </geometry>
    </visual>
    <collision>
      <origin rpy="0.0 0.0 0.0" xyz="0.0 0.0 0.0"/>
      <geometry>
        <box size="0.001 0.001 0.001"/>
      </geometry>
    </collision>
  </link>
  <joint name="R_thumb_proximal_joint" type="fixed">
    <origin rpy="0 0 0" xyz="0.011 0 0"/>
    <parent link="R_thumb_opp"/>
    <child link="R_thumb_proximal"/>
    <axis xyz="0 1 0"/>
    <limit effort="1000" lower="0.31536831160939" upper="0.957365354375099" velocity="1"/>
   
  </joint>
  <link name="R_thumb_proximal">
    <visual>
      <origin rpy="0 0 0" xyz="0 0 0"/>
      <geometry>
        <mesh filename="meshes/thumb_proximal.stl" scale="1e-3 1e-3 1e-3"/>
      </geometry>
    </visual>
    <collision>
      <origin rpy="0.0 0.0 0.0" xyz="0 0 0"/>
      <geometry>
        <box size="1e-3 1e-3 1e-3"/>
      </geometry>
    </collision>
    <inertial>
      <origin rpy="0.0 0.0 0.0" xyz="0.0037146239 0.0 0.025714396"/>
      <mass value="4.8359764e-07"/>
      <inertia ixx="1.1564874e-05" ixy="0.0" ixz="9.8057604e-07" iyy="1.2950704e-05" iyz="0.0" izz="4.7469757e-06"/>
    </inertial>
  </link>
  <joint name="R_thumb_middle_joint" type="fixed">
    <origin rpy="0 0 0" xyz="0 0 0.05572"/>
    <parent link="R_thumb_proximal"/>
    <child link="R_thumb_middle"/>
    <axis xyz="0 1 0"/>
    <mimic joint="R_thumb_proximal_joint" multiplier="1.257" offset="-1.192"/>
    <limit effort="1000" lower="0" upper="1" velocity="1"/>
   
  </joint>
  <link name="R_thumb_middle">
    <visual>
      <origin rpy="0 0 0" xyz="0 0 0"/>
      <geometry>
        <mesh filename="meshes/thumb_middle.stl" scale="1e-3 1e-3 1e-3"/>
      </geometry>
    </visual>
    <collision>
      <origin rpy="0.0 0.0 0.0" xyz="0 0 0"/>
      <geometry>
        <box size="1e-3 1e-3 1e-3"/>
      </geometry>
    </collision>
    <inertial>
      <origin rpy="0.0 0.0 0.0" xyz="0.0034051517 0 0.010727105"/>
      <mass value="7.5745038e-08"/>
      <inertia ixx="6.6016669e-07" ixy="0.0" ixz="-1.9329706e-08" iyy="6.3533864e-07" iyz="0.0" izz="6.546447e-07"/>
    </inertial>
  </link>
  <joint name="R_thumb_distal_joint" type="fixed">
    <origin rpy="0 0 0" xyz="0 0 0.02305"/>
    <parent link="R_thumb_middle"/>
    <child link="R_thumb_distal"/>
    <axis xyz="0 1 0"/>
    <mimic joint="R_thumb_proximal_joint" multiplier="1.009" offset="-0.85"/>
    <limit effort="1000" lower="0" upper="1" velocity="1"/>
  </joint>
  <link name="R_thumb_distal">
    <visual>
      <origin rpy="0 0 0" xyz="0 0 0"/>
      <geometry>
        <mesh filename="meshes/thumb_distal.stl" scale="1e-3 1e-3 1e-3"/>
      </geometry>
    </visual>
    <collision>
      <origin rpy="0.0 0.0 0.0" xyz="0 0 0"/>
      <geometry>
        <box size="1e-3 1e-3 1e-3"/>
      </geometry>
    </collision>
    <inertial>
      <origin rpy="0.0 0.0 0.0" xyz="0.00058212386 4.4266405e-06 0.014881067"/>
      <mass value="8.7566711e-07"/>
      <inertia ixx="1.0204087e-06" ixy="-8.9029655e-11" ixz="7.0098201e-08" iyy="9.9146034e-07" iyz="1.7085357e-10" izz="3.1951504e-07"/>
    </inertial>
  </link>

  <!-- hand point -->
  <joint name="AR_CONTACT" type="fixed">
    <origin rpy="0 0 0" xyz="0 0.05 -0.17"/>
    <parent link="R_palm"/>
    <child link="R_HAND_CONTACT"/>
  </joint>
  <link name="R_HAND_CONTACT"/>
  <joint name="AL_CONTACT" type="fixed">
    <origin rpy="0 0 0" xyz="0 -0.05 -0.17"/>
    <parent link="L_palm"/>
    <child link="L_HAND_CONTACT"/>
  </joint>
  <link name="L_HAND_CONTACT"/>
  <!-- torso point -->
  <joint name="TOR_CONTACT" type="fixed">
    <origin rpy="0 0 0" xyz="0 0 0"/>
    <parent link="trunk"/>
    <child link="TORSO_CONTACT"/>
  </joint>
  <link name="TORSO_CONTACT"/>
  <!-- sole point -->
  <joint name="LL_CONTACT" type="fixed">
    <origin rpy="0 0 0" xyz="0 0 -0.049"/>
    <parent link="L_foot"/>
    <child link="L_FOOT_CONTACT"/>
  </joint>
  <link name="L_FOOT_CONTACT"/>
  <joint name="LR_CONTACT" type="fixed">
    <origin rpy="0 0 0" xyz="0 0 -0.049"/>
    <parent link="R_foot"/>
    <child link="R_FOOT_CONTACT"/>
  </joint>
  <link name="R_FOOT_CONTACT"/>
  
  <!-- 8 points for 2 feet -->
  <joint name="LLT_CONTACT" type="fixed">
    <origin rpy="0 0 0" xyz="0.17 0.04 -0.049"/>
    <parent link="L_foot"/>
    <child link="LLT_FOOT_CONTACT"/>
  </joint>
  <link name="LLT_FOOT_CONTACT"/>
  <joint name="LRT_CONTACT" type="fixed">
    <origin rpy="0 0 0" xyz="0.17 -0.04 -0.049"/>
    <parent link="L_foot"/>
    <child link="LRT_FOOT_CONTACT"/>
  </joint>
  <link name="LRT_FOOT_CONTACT"/>
  <joint name="LLH_CONTACT" type="fixed">
    <origin rpy="0 0 0" xyz="-0.050 0.04 -0.049"/>
    <parent link="L_foot"/>
    <child link="LLH_FOOT_CONTACT"/>
  </joint>
  <link name="LLH_FOOT_CONTACT"/>
  <joint name="LRH_CONTACT" type="fixed">
    <origin rpy="0 0 0" xyz="-0.050 -0.04 -0.049"/>
    <parent link="L_foot"/>
    <child link="LRH_FOOT_CONTACT"/>
  </joint>
  <link name="LRH_FOOT_CONTACT"/>
  <joint name="RLT_CONTACT" type="fixed">
    <origin rpy="0 0 0" xyz="0.17 0.04 -0.049"/>
    <parent link="R_foot"/>
    <child link="RLT_FOOT_CONTACT"/>
  </joint>
  <link name="RLT_FOOT_CONTACT"/>
  <joint name="RRT_CONTACT" type="fixed">
    <origin rpy="0 0 0" xyz="0.17 -0.04 -0.049"/>
    <parent link="R_foot"/>
    <child link="RRT_FOOT_CONTACT"/>
  </joint>
  <link name="RRT_FOOT_CONTACT"/>
  <joint name="RLH_CONTACT" type="fixed">
    <origin rpy="0 0 0" xyz="-0.050 0.04 -0.049"/>
    <parent link="R_foot"/>
    <child link="RLH_FOOT_CONTACT"/>
  </joint>
  <link name="RLH_FOOT_CONTACT"/>
  <joint name="RRH_CONTACT" type="fixed">
    <origin rpy="0 0 0" xyz="-0.050 -0.04 -0.049"/>
    <parent link="R_foot"/>
    <child link="RRH_FOOT_CONTACT"/>
  </joint>
  <link name="RRH_FOOT_CONTACT"/>
</robot>
